<?xml version="1.0" ?>
<!-- =================================================================================== -->
<!-- |    This document was autogenerated by xacro from dif_bot_description.urdf.xacro | -->
<!-- |    EDITING THIS FILE BY HAND IS NOT RECOMMENDED                                 | -->
<!-- =================================================================================== -->
<robot name="dif_bot">
  <!-- Base -->
  <link name="base_link">
    <visual>
      <geometry>
        <box size="0.4 0.3 0.1"/>
      </geometry>
      <material>
        <color rgba="0.8 0.2 0.2 1"/>
      </material>
    </visual>
  </link>
  <!-- Rueda izquierda -->
  <link name="left_wheel">
    <visual>
      <geometry>
        <cylinder length="0.02" radius="0.05"/>
      </geometry>
      <material>
        <color rgba="0.2 0.2 0.8 1"/>
      </material>
    </visual>
  </link>
  <joint name="left_wheel_joint" type="continuous">
    <parent link="base_link"/>
    <child link="left_wheel"/>
    <origin rpy="0 0 0" xyz="0 0.15 0"/>
    <axis xyz="0 1 0"/>
  </joint>
  <!-- Rueda derecha -->
  <link name="right_wheel">
    <visual>
      <geometry>
        <cylinder length="0.02" radius="0.05"/>
      </geometry>
      <material>
        <color rgba="0.2 0.8 0.2 1"/>
      </material>
    </visual>
  </link>
  <joint name="right_wheel_joint" type="continuous">
    <parent link="base_link"/>
    <child link="right_wheel"/>
    <origin rpy="0 0 0" xyz="0 -0.15 0"/>
    <axis xyz="0 1 0"/>
  </joint>
  <!-- Caster -->
  <link name="caster">
    <visual>
      <geometry>
        <sphere radius="0.03"/>
      </geometry>
      <material>
        <color rgba="0.8 0.8 0.2 1"/>
      </material>
    </visual>
  </link>
  <joint name="caster_joint" type="fixed">
    <parent link="base_link"/>
    <child link="caster"/>
    <origin rpy="0 0 0" xyz="-0.2 0 -0.03"/>
  </joint>
</robot>
